<?xml version="1.0" encoding="utf-8"?>
<!-- This URDF was automatically created by SolidWorks to URDF Exporter! Originally created by Stephen Brawner (brawner@gmail.com) 
     Commit Version: 1.6.0-4-g7f85cfe  Build Version: 1.6.7995.38578
     For more information, please see http://wiki.ros.org/sw_urdf_exporter -->
<robot
  name="xmate">
  <link 
    name="base_link">
    <inertial>
      <origin
        xyz="-0.019091 4.6236E-05 0.062409"
        rpy="0 0 0" />
      <mass
        value="3.149" />
      <inertia
        ixx="0.01181"
        ixy="1.0531E-05"
        ixz="-0.0018001"
        iyy="0.015849"
        iyz="1.0822E-06"
        izz="0.012972" />
    </inertial>
    <visual>
      <origin
        xyz="0 0 0"
        rpy="0 0 0" />
      <geometry>
        <mesh
          filename="package://xmate_description/meshes/base_link.STL" />
      </geometry>
      <material
        name="">
        <color
          rgba="1 1 1 1" />
      </material>
    </visual>
    <collision>
      <origin
        xyz="0 0 0"
        rpy="0 0 0" />
      <geometry>
        <mesh
          filename="package://xmate_description/meshes/base_link.STL" />
      </geometry>
    </collision>
  </link>
  <link
    name="Link1">
    <inertial>
      <origin
        xyz="2.0957E-06 -0.025273 0.10055"
        rpy="0 0 0" />
      <mass
        value="1.8004" />
      <inertia
        ixx="0.0095699"
        ixy="-5.5499E-07"
        ixz="-5.9388E-07"
        iyy="0.0085643"
        iyz="0.0019573"
        izz="0.0033056" />
    </inertial>
    <visual>
      <origin
        xyz="0 0 0"
        rpy="0 0 0" />
      <geometry>
        <mesh
          filename="package://xmate_description/meshes/Link1.STL" />
      </geometry>
      <material
        name="">
        <color
          rgba="1 1 1 1" />
      </material>
    </visual>
    <collision>
      <origin
        xyz="0 0 0"
        rpy="0 0 0" />
      <geometry>
        <mesh
          filename="package://xmate_description/meshes/Link1.STL" />
      </geometry>
    </collision>
  </link>
  <joint
    name="joint1"
    type="revolute">
    <origin
      xyz="0 0 0.1875"
      rpy="0 0 0" />
    <parent
      link="base_link" />
    <child
      link="Link1" />
    <axis
      xyz="0 0 1" />
    <limit
      lower="-2.967"
      upper="2.967"
      effort="94"
      velocity="3.14" />
  </joint>
  <link
    name="Link2">
    <inertial>
      <origin
        xyz="-7.7231E-06 0.0080655 0.094982"
        rpy="0 0 0" />
      <mass
        value="2.1851" />
      <inertia
        ixx="0.01796"
        ixy="6.7065E-07"
        ixz="-1.9282E-07"
        iyy="0.016293"
        iyz="0.004567"
        izz="0.0044669" />
    </inertial>
    <visual>
      <origin
        xyz="0 0 0"
        rpy="0 0 0" />
      <geometry>
        <mesh
          filename="package://xmate_description/meshes/Link2.STL" />
      </geometry>
      <material
        name="">
        <color
          rgba="1 1 1 1" />
      </material>
    </visual>
    <collision>
      <origin
        xyz="0 0 0"
        rpy="0 0 0" />
      <geometry>
        <mesh
          filename="package://xmate_description/meshes/Link2.STL" />
      </geometry>
    </collision>
  </link>
  <joint
    name="joint2"
    type="revolute">
    <origin
      xyz="0 0.019574 0.1537"
      rpy="0 0 0" />
    <parent
      link="Link1" />
    <child
      link="Link2" />
    <axis
      xyz="0 1 0" />
    <limit
      lower="-2.094"
      upper="2.094"
      effort="110"
      velocity="3.14" />
  </joint>
  <link
    name="Link3">
    <inertial>
      <origin
        xyz="1.7981E-06 -0.025268 0.10695"
        rpy="0 0 0" />
      <mass
        value="1.8005" />
      <inertia
        ixx="0.0095706"
        ixy="-5.6305E-07"
        ixz="-6.0731E-07"
        iyy="0.0085644"
        iyz="0.0019583"
        izz="0.0033062" />
    </inertial>
    <visual>
      <origin
        xyz="0 0 0"
        rpy="0 0 0" />
      <geometry>
        <mesh
          filename="package://xmate_description/meshes/Link3.STL" />
      </geometry>
      <material
        name="">
        <color
          rgba="1 1 1 1" />
      </material>
    </visual>
    <collision>
      <origin
        xyz="0 0 0"
        rpy="0 0 0" />
      <geometry>
        <mesh
          filename="package://xmate_description/meshes/Link3.STL" />
      </geometry>
    </collision>
  </link>
  <joint
    name="joint3"
    type="revolute">
    <origin
      xyz="0 -0.019574 0.2339"
      rpy="0 0 0" />
    <parent
      link="Link2" />
    <child
      link="Link3" />
    <axis
      xyz="0 0 1" />
    <limit
      lower="-2.967"
      upper="2.967"
      effort="94"
      velocity="3.14" />
  </joint>
  <link
    name="Link4">
    <inertial>
      <origin
        xyz="3.8223E-06 0.013309 0.075673"
        rpy="0 0 0" />
      <mass
        value="1.8003" />
      <inertia
        ixx="0.013101"
        ixy="1.9071E-07"
        ixz="-6.6439E-07"
        iyy="0.011754"
        iyz="0.0034777"
        izz="0.0033663" />
    </inertial>
    <visual>
      <origin
        xyz="0 0 0"
        rpy="0 0 0" />
      <geometry>
        <mesh
          filename="package://xmate_description/meshes/Link4.STL" />
      </geometry>
      <material
        name="">
        <color
          rgba="1 1 1 1" />
      </material>
    </visual>
    <collision>
      <origin
        xyz="0 0 0"
        rpy="0 0 0" />
      <geometry>
        <mesh
          filename="package://xmate_description/meshes/Link4.STL" />
      </geometry>
    </collision>
  </link>
  <joint
    name="joint4"
    type="revolute">
    <origin
      xyz="0 0.0196 0.1604"
      rpy="0 0 0" />
    <parent
      link="Link3" />
    <child
      link="Link4" />
    <axis
      xyz="0 1 0" />
    <limit
      lower="-2.094"
      upper="2.094"
      effort="94"
      velocity="3.14" />
  </joint>
  <link
    name="Link5">
    <inertial>
      <origin
        xyz="-0.00022851 -0.031271 0.089895"
        rpy="0 0 0" />
      <mass
        value="1.2959" />
      <inertia
        ixx="0.0059856"
        ixy="-4.2315E-07"
        ixz="4.9288E-07"
        iyy="0.0048985"
        iyz="0.0015266"
        izz="0.0022675" />
    </inertial>
    <visual>
      <origin
        xyz="0 0 0"
        rpy="0 0 0" />
      <geometry>
        <mesh
          filename="package://xmate_description/meshes/Link5.STL" />
      </geometry>
      <material
        name="">
        <color
          rgba="1 1 1 1" />
      </material>
    </visual>
    <collision>
      <origin
        xyz="0 0 0"
        rpy="0 0 0" />
      <geometry>
        <mesh
          filename="package://xmate_description/meshes/Link5.STL" />
      </geometry>
    </collision>
  </link>
  <joint
    name="joint5"
    type="revolute">
    <origin
      xyz="0.00024323 -0.019605 0.23041"
      rpy="0 0 0" />
    <parent
      link="Link4" />
    <child
      link="Link5" />
    <axis
      xyz="0 0 1" />
    <limit
      lower="-2.967"
      upper="2.967"
      effort="29"
      velocity="3.14" />
  </joint>
  <link
    name="Link6">
    <inertial>
      <origin
        xyz="1.1944E-05 0.0054276 0.084293"
        rpy="0 0 0" />
      <mass
        value="1.2251" />
      <inertia
        ixx="0.006284"
        ixy="-1.5126E-07"
        ixz="3.4283E-07"
        iyy="0.0059857"
        iyz="0.0012842"
        izz="0.0014649" />
    </inertial>
    <visual>
      <origin
        xyz="0 0 0"
        rpy="0 0 0" />
      <geometry>
        <mesh
          filename="package://xmate_description/meshes/Link6.STL" />
      </geometry>
      <material
        name="">
        <color
          rgba="1 1 1 1" />
      </material>
    </visual>
    <collision>
      <origin
        xyz="0 0 0"
        rpy="0 0 0" />
      <geometry>
        <mesh
          filename="package://xmate_description/meshes/Link6.STL" />
      </geometry>
    </collision>
  </link>
  <joint
    name="joint6"
    type="revolute">
    <origin
      xyz="-0.00024274 0.0097253 0.13559"
      rpy="0 0 0" />
    <parent
      link="Link5" />
    <child
      link="Link6" />
    <axis
      xyz="0 1 0" />
    <limit
      lower="-2.094"
      upper="2.094"
      effort="29"
      velocity="3.14" />
  </joint>
  <link
    name="Link7">
    <inertial>
      <origin
        xyz="4.6311E-05 0.023055 0.014446"
        rpy="0 0 0" />
      <mass
        value="0.54271" />
      <inertia
        ixx="0.0011662"
        ixy="-2.3556E-07"
        ixz="-4.2707E-07"
        iyy="0.00063847"
        iyz="0.0002823"
        izz="0.0009518" />
    </inertial>
    <visual>
      <origin
        xyz="0 0 0"
        rpy="0 0 0" />
      <geometry>
        <mesh
          filename="package://xmate_description/meshes/Link7.STL" />
      </geometry>
      <material
        name="">
        <color
          rgba="1 1 1 1" />
      </material>
    </visual>
    <collision>
      <origin
        xyz="0 0 0"
        rpy="0 0 0" />
      <geometry>
        <mesh
          filename="package://xmate_description/meshes/Link7.STL" />
      </geometry>
    </collision>
  </link>
  <joint
    name="joint7"
    type="revolute">
    <origin
      xyz="0 -0.00972 0.1911"
      rpy="0 0 0" />
    <parent
      link="Link6" />
    <child
      link="Link7" />
    <axis
      xyz="0 0 1" />
    <limit
      lower="-6.28"
      upper="6.28"
      effort="29"
      velocity="3.14" />
  </joint>
</robot>